{
 "cells": [
  {
   "cell_type": "code",
   "execution_count": 5,
   "id": "6cdc82d6",
   "metadata": {},
   "outputs": [
    {
     "ename": "SyntaxError",
     "evalue": "invalid syntax (1083941561.py, line 5)",
     "output_type": "error",
     "traceback": [
      "\u001b[1;36m  Input \u001b[1;32mIn [5]\u001b[1;36m\u001b[0m\n\u001b[1;33m    jovian configure()\u001b[0m\n\u001b[1;37m           ^\u001b[0m\n\u001b[1;31mSyntaxError\u001b[0m\u001b[1;31m:\u001b[0m invalid syntax\n"
     ]
    }
   ],
   "source": [
    "import os\n",
    "import datetime\n",
    "import shutil\n",
    "import jovian"
   ]
  },
  {
   "cell_type": "code",
   "execution_count": 8,
   "id": "1dac25de",
   "metadata": {},
   "outputs": [
    {
     "name": "stdout",
     "output_type": "stream",
     "text": [
      "[jovian] If you're a jovian-pro user please enter your company's organization ID on Jovian (otherwise leave it blank).\u001b[0m\n",
      "Organization ID: \n",
      "  @media print {\n",
      "    .ms-editor-squiggles-container {\n",
      "      display:none !important;\n",
      "    }\n",
      "  }\n",
      "  .ms-editor-squiggles-container {\n",
      "    all: initial;\n",
      "  }nihitkr-chp\n"
     ]
    },
    {
     "ename": "ConnectionError",
     "evalue": "HTTPSConnectionPool(host='nihitkr-chp.jovian.ai', port=443): Max retries exceeded with url: /config.json (Caused by NewConnectionError('<urllib3.connection.HTTPSConnection object at 0x00000213E3BD5B50>: Failed to establish a new connection: [Errno 11001] getaddrinfo failed'))",
     "output_type": "error",
     "traceback": [
      "\u001b[1;31m---------------------------------------------------------------------------\u001b[0m",
      "\u001b[1;31mgaierror\u001b[0m                                  Traceback (most recent call last)",
      "File \u001b[1;32m~\\anaconda3\\lib\\site-packages\\urllib3\\connection.py:174\u001b[0m, in \u001b[0;36mHTTPConnection._new_conn\u001b[1;34m(self)\u001b[0m\n\u001b[0;32m    173\u001b[0m \u001b[38;5;28;01mtry\u001b[39;00m:\n\u001b[1;32m--> 174\u001b[0m     conn \u001b[38;5;241m=\u001b[39m connection\u001b[38;5;241m.\u001b[39mcreate_connection(\n\u001b[0;32m    175\u001b[0m         (\u001b[38;5;28mself\u001b[39m\u001b[38;5;241m.\u001b[39m_dns_host, \u001b[38;5;28mself\u001b[39m\u001b[38;5;241m.\u001b[39mport), \u001b[38;5;28mself\u001b[39m\u001b[38;5;241m.\u001b[39mtimeout, \u001b[38;5;241m*\u001b[39m\u001b[38;5;241m*\u001b[39mextra_kw\n\u001b[0;32m    176\u001b[0m     )\n\u001b[0;32m    178\u001b[0m \u001b[38;5;28;01mexcept\u001b[39;00m SocketTimeout:\n",
      "File \u001b[1;32m~\\anaconda3\\lib\\site-packages\\urllib3\\util\\connection.py:72\u001b[0m, in \u001b[0;36mcreate_connection\u001b[1;34m(address, timeout, source_address, socket_options)\u001b[0m\n\u001b[0;32m     68\u001b[0m     \u001b[38;5;28;01mreturn\u001b[39;00m six\u001b[38;5;241m.\u001b[39mraise_from(\n\u001b[0;32m     69\u001b[0m         LocationParseError(\u001b[38;5;124mu\u001b[39m\u001b[38;5;124m\"\u001b[39m\u001b[38;5;124m'\u001b[39m\u001b[38;5;132;01m%s\u001b[39;00m\u001b[38;5;124m'\u001b[39m\u001b[38;5;124m, label empty or too long\u001b[39m\u001b[38;5;124m\"\u001b[39m \u001b[38;5;241m%\u001b[39m host), \u001b[38;5;28;01mNone\u001b[39;00m\n\u001b[0;32m     70\u001b[0m     )\n\u001b[1;32m---> 72\u001b[0m \u001b[38;5;28;01mfor\u001b[39;00m res \u001b[38;5;129;01min\u001b[39;00m \u001b[43msocket\u001b[49m\u001b[38;5;241;43m.\u001b[39;49m\u001b[43mgetaddrinfo\u001b[49m\u001b[43m(\u001b[49m\u001b[43mhost\u001b[49m\u001b[43m,\u001b[49m\u001b[43m \u001b[49m\u001b[43mport\u001b[49m\u001b[43m,\u001b[49m\u001b[43m \u001b[49m\u001b[43mfamily\u001b[49m\u001b[43m,\u001b[49m\u001b[43m \u001b[49m\u001b[43msocket\u001b[49m\u001b[38;5;241;43m.\u001b[39;49m\u001b[43mSOCK_STREAM\u001b[49m\u001b[43m)\u001b[49m:\n\u001b[0;32m     73\u001b[0m     af, socktype, proto, canonname, sa \u001b[38;5;241m=\u001b[39m res\n",
      "File \u001b[1;32m~\\anaconda3\\lib\\socket.py:954\u001b[0m, in \u001b[0;36mgetaddrinfo\u001b[1;34m(host, port, family, type, proto, flags)\u001b[0m\n\u001b[0;32m    953\u001b[0m addrlist \u001b[38;5;241m=\u001b[39m []\n\u001b[1;32m--> 954\u001b[0m \u001b[38;5;28;01mfor\u001b[39;00m res \u001b[38;5;129;01min\u001b[39;00m \u001b[43m_socket\u001b[49m\u001b[38;5;241;43m.\u001b[39;49m\u001b[43mgetaddrinfo\u001b[49m\u001b[43m(\u001b[49m\u001b[43mhost\u001b[49m\u001b[43m,\u001b[49m\u001b[43m \u001b[49m\u001b[43mport\u001b[49m\u001b[43m,\u001b[49m\u001b[43m \u001b[49m\u001b[43mfamily\u001b[49m\u001b[43m,\u001b[49m\u001b[43m \u001b[49m\u001b[38;5;28;43mtype\u001b[39;49m\u001b[43m,\u001b[49m\u001b[43m \u001b[49m\u001b[43mproto\u001b[49m\u001b[43m,\u001b[49m\u001b[43m \u001b[49m\u001b[43mflags\u001b[49m\u001b[43m)\u001b[49m:\n\u001b[0;32m    955\u001b[0m     af, socktype, proto, canonname, sa \u001b[38;5;241m=\u001b[39m res\n",
      "\u001b[1;31mgaierror\u001b[0m: [Errno 11001] getaddrinfo failed",
      "\nDuring handling of the above exception, another exception occurred:\n",
      "\u001b[1;31mNewConnectionError\u001b[0m                        Traceback (most recent call last)",
      "File \u001b[1;32m~\\anaconda3\\lib\\site-packages\\urllib3\\connectionpool.py:703\u001b[0m, in \u001b[0;36mHTTPConnectionPool.urlopen\u001b[1;34m(self, method, url, body, headers, retries, redirect, assert_same_host, timeout, pool_timeout, release_conn, chunked, body_pos, **response_kw)\u001b[0m\n\u001b[0;32m    702\u001b[0m \u001b[38;5;66;03m# Make the request on the httplib connection object.\u001b[39;00m\n\u001b[1;32m--> 703\u001b[0m httplib_response \u001b[38;5;241m=\u001b[39m \u001b[38;5;28;43mself\u001b[39;49m\u001b[38;5;241;43m.\u001b[39;49m\u001b[43m_make_request\u001b[49m\u001b[43m(\u001b[49m\n\u001b[0;32m    704\u001b[0m \u001b[43m    \u001b[49m\u001b[43mconn\u001b[49m\u001b[43m,\u001b[49m\n\u001b[0;32m    705\u001b[0m \u001b[43m    \u001b[49m\u001b[43mmethod\u001b[49m\u001b[43m,\u001b[49m\n\u001b[0;32m    706\u001b[0m \u001b[43m    \u001b[49m\u001b[43murl\u001b[49m\u001b[43m,\u001b[49m\n\u001b[0;32m    707\u001b[0m \u001b[43m    \u001b[49m\u001b[43mtimeout\u001b[49m\u001b[38;5;241;43m=\u001b[39;49m\u001b[43mtimeout_obj\u001b[49m\u001b[43m,\u001b[49m\n\u001b[0;32m    708\u001b[0m \u001b[43m    \u001b[49m\u001b[43mbody\u001b[49m\u001b[38;5;241;43m=\u001b[39;49m\u001b[43mbody\u001b[49m\u001b[43m,\u001b[49m\n\u001b[0;32m    709\u001b[0m \u001b[43m    \u001b[49m\u001b[43mheaders\u001b[49m\u001b[38;5;241;43m=\u001b[39;49m\u001b[43mheaders\u001b[49m\u001b[43m,\u001b[49m\n\u001b[0;32m    710\u001b[0m \u001b[43m    \u001b[49m\u001b[43mchunked\u001b[49m\u001b[38;5;241;43m=\u001b[39;49m\u001b[43mchunked\u001b[49m\u001b[43m,\u001b[49m\n\u001b[0;32m    711\u001b[0m \u001b[43m\u001b[49m\u001b[43m)\u001b[49m\n\u001b[0;32m    713\u001b[0m \u001b[38;5;66;03m# If we're going to release the connection in ``finally:``, then\u001b[39;00m\n\u001b[0;32m    714\u001b[0m \u001b[38;5;66;03m# the response doesn't need to know about the connection. Otherwise\u001b[39;00m\n\u001b[0;32m    715\u001b[0m \u001b[38;5;66;03m# it will also try to release it and we'll have a double-release\u001b[39;00m\n\u001b[0;32m    716\u001b[0m \u001b[38;5;66;03m# mess.\u001b[39;00m\n",
      "File \u001b[1;32m~\\anaconda3\\lib\\site-packages\\urllib3\\connectionpool.py:386\u001b[0m, in \u001b[0;36mHTTPConnectionPool._make_request\u001b[1;34m(self, conn, method, url, timeout, chunked, **httplib_request_kw)\u001b[0m\n\u001b[0;32m    385\u001b[0m \u001b[38;5;28;01mtry\u001b[39;00m:\n\u001b[1;32m--> 386\u001b[0m     \u001b[38;5;28;43mself\u001b[39;49m\u001b[38;5;241;43m.\u001b[39;49m\u001b[43m_validate_conn\u001b[49m\u001b[43m(\u001b[49m\u001b[43mconn\u001b[49m\u001b[43m)\u001b[49m\n\u001b[0;32m    387\u001b[0m \u001b[38;5;28;01mexcept\u001b[39;00m (SocketTimeout, BaseSSLError) \u001b[38;5;28;01mas\u001b[39;00m e:\n\u001b[0;32m    388\u001b[0m     \u001b[38;5;66;03m# Py2 raises this as a BaseSSLError, Py3 raises it as socket timeout.\u001b[39;00m\n",
      "File \u001b[1;32m~\\anaconda3\\lib\\site-packages\\urllib3\\connectionpool.py:1040\u001b[0m, in \u001b[0;36mHTTPSConnectionPool._validate_conn\u001b[1;34m(self, conn)\u001b[0m\n\u001b[0;32m   1039\u001b[0m \u001b[38;5;28;01mif\u001b[39;00m \u001b[38;5;129;01mnot\u001b[39;00m \u001b[38;5;28mgetattr\u001b[39m(conn, \u001b[38;5;124m\"\u001b[39m\u001b[38;5;124msock\u001b[39m\u001b[38;5;124m\"\u001b[39m, \u001b[38;5;28;01mNone\u001b[39;00m):  \u001b[38;5;66;03m# AppEngine might not have  `.sock`\u001b[39;00m\n\u001b[1;32m-> 1040\u001b[0m     \u001b[43mconn\u001b[49m\u001b[38;5;241;43m.\u001b[39;49m\u001b[43mconnect\u001b[49m\u001b[43m(\u001b[49m\u001b[43m)\u001b[49m\n\u001b[0;32m   1042\u001b[0m \u001b[38;5;28;01mif\u001b[39;00m \u001b[38;5;129;01mnot\u001b[39;00m conn\u001b[38;5;241m.\u001b[39mis_verified:\n",
      "File \u001b[1;32m~\\anaconda3\\lib\\site-packages\\urllib3\\connection.py:358\u001b[0m, in \u001b[0;36mHTTPSConnection.connect\u001b[1;34m(self)\u001b[0m\n\u001b[0;32m    356\u001b[0m \u001b[38;5;28;01mdef\u001b[39;00m \u001b[38;5;21mconnect\u001b[39m(\u001b[38;5;28mself\u001b[39m):\n\u001b[0;32m    357\u001b[0m     \u001b[38;5;66;03m# Add certificate verification\u001b[39;00m\n\u001b[1;32m--> 358\u001b[0m     \u001b[38;5;28mself\u001b[39m\u001b[38;5;241m.\u001b[39msock \u001b[38;5;241m=\u001b[39m conn \u001b[38;5;241m=\u001b[39m \u001b[38;5;28;43mself\u001b[39;49m\u001b[38;5;241;43m.\u001b[39;49m\u001b[43m_new_conn\u001b[49m\u001b[43m(\u001b[49m\u001b[43m)\u001b[49m\n\u001b[0;32m    359\u001b[0m     hostname \u001b[38;5;241m=\u001b[39m \u001b[38;5;28mself\u001b[39m\u001b[38;5;241m.\u001b[39mhost\n",
      "File \u001b[1;32m~\\anaconda3\\lib\\site-packages\\urllib3\\connection.py:186\u001b[0m, in \u001b[0;36mHTTPConnection._new_conn\u001b[1;34m(self)\u001b[0m\n\u001b[0;32m    185\u001b[0m \u001b[38;5;28;01mexcept\u001b[39;00m SocketError \u001b[38;5;28;01mas\u001b[39;00m e:\n\u001b[1;32m--> 186\u001b[0m     \u001b[38;5;28;01mraise\u001b[39;00m NewConnectionError(\n\u001b[0;32m    187\u001b[0m         \u001b[38;5;28mself\u001b[39m, \u001b[38;5;124m\"\u001b[39m\u001b[38;5;124mFailed to establish a new connection: \u001b[39m\u001b[38;5;132;01m%s\u001b[39;00m\u001b[38;5;124m\"\u001b[39m \u001b[38;5;241m%\u001b[39m e\n\u001b[0;32m    188\u001b[0m     )\n\u001b[0;32m    190\u001b[0m \u001b[38;5;28;01mreturn\u001b[39;00m conn\n",
      "\u001b[1;31mNewConnectionError\u001b[0m: <urllib3.connection.HTTPSConnection object at 0x00000213E3BD5B50>: Failed to establish a new connection: [Errno 11001] getaddrinfo failed",
      "\nDuring handling of the above exception, another exception occurred:\n",
      "\u001b[1;31mMaxRetryError\u001b[0m                             Traceback (most recent call last)",
      "File \u001b[1;32m~\\anaconda3\\lib\\site-packages\\requests\\adapters.py:440\u001b[0m, in \u001b[0;36mHTTPAdapter.send\u001b[1;34m(self, request, stream, timeout, verify, cert, proxies)\u001b[0m\n\u001b[0;32m    439\u001b[0m \u001b[38;5;28;01mif\u001b[39;00m \u001b[38;5;129;01mnot\u001b[39;00m chunked:\n\u001b[1;32m--> 440\u001b[0m     resp \u001b[38;5;241m=\u001b[39m \u001b[43mconn\u001b[49m\u001b[38;5;241;43m.\u001b[39;49m\u001b[43murlopen\u001b[49m\u001b[43m(\u001b[49m\n\u001b[0;32m    441\u001b[0m \u001b[43m        \u001b[49m\u001b[43mmethod\u001b[49m\u001b[38;5;241;43m=\u001b[39;49m\u001b[43mrequest\u001b[49m\u001b[38;5;241;43m.\u001b[39;49m\u001b[43mmethod\u001b[49m\u001b[43m,\u001b[49m\n\u001b[0;32m    442\u001b[0m \u001b[43m        \u001b[49m\u001b[43murl\u001b[49m\u001b[38;5;241;43m=\u001b[39;49m\u001b[43murl\u001b[49m\u001b[43m,\u001b[49m\n\u001b[0;32m    443\u001b[0m \u001b[43m        \u001b[49m\u001b[43mbody\u001b[49m\u001b[38;5;241;43m=\u001b[39;49m\u001b[43mrequest\u001b[49m\u001b[38;5;241;43m.\u001b[39;49m\u001b[43mbody\u001b[49m\u001b[43m,\u001b[49m\n\u001b[0;32m    444\u001b[0m \u001b[43m        \u001b[49m\u001b[43mheaders\u001b[49m\u001b[38;5;241;43m=\u001b[39;49m\u001b[43mrequest\u001b[49m\u001b[38;5;241;43m.\u001b[39;49m\u001b[43mheaders\u001b[49m\u001b[43m,\u001b[49m\n\u001b[0;32m    445\u001b[0m \u001b[43m        \u001b[49m\u001b[43mredirect\u001b[49m\u001b[38;5;241;43m=\u001b[39;49m\u001b[38;5;28;43;01mFalse\u001b[39;49;00m\u001b[43m,\u001b[49m\n\u001b[0;32m    446\u001b[0m \u001b[43m        \u001b[49m\u001b[43massert_same_host\u001b[49m\u001b[38;5;241;43m=\u001b[39;49m\u001b[38;5;28;43;01mFalse\u001b[39;49;00m\u001b[43m,\u001b[49m\n\u001b[0;32m    447\u001b[0m \u001b[43m        \u001b[49m\u001b[43mpreload_content\u001b[49m\u001b[38;5;241;43m=\u001b[39;49m\u001b[38;5;28;43;01mFalse\u001b[39;49;00m\u001b[43m,\u001b[49m\n\u001b[0;32m    448\u001b[0m \u001b[43m        \u001b[49m\u001b[43mdecode_content\u001b[49m\u001b[38;5;241;43m=\u001b[39;49m\u001b[38;5;28;43;01mFalse\u001b[39;49;00m\u001b[43m,\u001b[49m\n\u001b[0;32m    449\u001b[0m \u001b[43m        \u001b[49m\u001b[43mretries\u001b[49m\u001b[38;5;241;43m=\u001b[39;49m\u001b[38;5;28;43mself\u001b[39;49m\u001b[38;5;241;43m.\u001b[39;49m\u001b[43mmax_retries\u001b[49m\u001b[43m,\u001b[49m\n\u001b[0;32m    450\u001b[0m \u001b[43m        \u001b[49m\u001b[43mtimeout\u001b[49m\u001b[38;5;241;43m=\u001b[39;49m\u001b[43mtimeout\u001b[49m\n\u001b[0;32m    451\u001b[0m \u001b[43m    \u001b[49m\u001b[43m)\u001b[49m\n\u001b[0;32m    453\u001b[0m \u001b[38;5;66;03m# Send the request.\u001b[39;00m\n\u001b[0;32m    454\u001b[0m \u001b[38;5;28;01melse\u001b[39;00m:\n",
      "File \u001b[1;32m~\\anaconda3\\lib\\site-packages\\urllib3\\connectionpool.py:785\u001b[0m, in \u001b[0;36mHTTPConnectionPool.urlopen\u001b[1;34m(self, method, url, body, headers, retries, redirect, assert_same_host, timeout, pool_timeout, release_conn, chunked, body_pos, **response_kw)\u001b[0m\n\u001b[0;32m    783\u001b[0m     e \u001b[38;5;241m=\u001b[39m ProtocolError(\u001b[38;5;124m\"\u001b[39m\u001b[38;5;124mConnection aborted.\u001b[39m\u001b[38;5;124m\"\u001b[39m, e)\n\u001b[1;32m--> 785\u001b[0m retries \u001b[38;5;241m=\u001b[39m \u001b[43mretries\u001b[49m\u001b[38;5;241;43m.\u001b[39;49m\u001b[43mincrement\u001b[49m\u001b[43m(\u001b[49m\n\u001b[0;32m    786\u001b[0m \u001b[43m    \u001b[49m\u001b[43mmethod\u001b[49m\u001b[43m,\u001b[49m\u001b[43m \u001b[49m\u001b[43murl\u001b[49m\u001b[43m,\u001b[49m\u001b[43m \u001b[49m\u001b[43merror\u001b[49m\u001b[38;5;241;43m=\u001b[39;49m\u001b[43me\u001b[49m\u001b[43m,\u001b[49m\u001b[43m \u001b[49m\u001b[43m_pool\u001b[49m\u001b[38;5;241;43m=\u001b[39;49m\u001b[38;5;28;43mself\u001b[39;49m\u001b[43m,\u001b[49m\u001b[43m \u001b[49m\u001b[43m_stacktrace\u001b[49m\u001b[38;5;241;43m=\u001b[39;49m\u001b[43msys\u001b[49m\u001b[38;5;241;43m.\u001b[39;49m\u001b[43mexc_info\u001b[49m\u001b[43m(\u001b[49m\u001b[43m)\u001b[49m\u001b[43m[\u001b[49m\u001b[38;5;241;43m2\u001b[39;49m\u001b[43m]\u001b[49m\n\u001b[0;32m    787\u001b[0m \u001b[43m\u001b[49m\u001b[43m)\u001b[49m\n\u001b[0;32m    788\u001b[0m retries\u001b[38;5;241m.\u001b[39msleep()\n",
      "File \u001b[1;32m~\\anaconda3\\lib\\site-packages\\urllib3\\util\\retry.py:592\u001b[0m, in \u001b[0;36mRetry.increment\u001b[1;34m(self, method, url, response, error, _pool, _stacktrace)\u001b[0m\n\u001b[0;32m    591\u001b[0m \u001b[38;5;28;01mif\u001b[39;00m new_retry\u001b[38;5;241m.\u001b[39mis_exhausted():\n\u001b[1;32m--> 592\u001b[0m     \u001b[38;5;28;01mraise\u001b[39;00m MaxRetryError(_pool, url, error \u001b[38;5;129;01mor\u001b[39;00m ResponseError(cause))\n\u001b[0;32m    594\u001b[0m log\u001b[38;5;241m.\u001b[39mdebug(\u001b[38;5;124m\"\u001b[39m\u001b[38;5;124mIncremented Retry for (url=\u001b[39m\u001b[38;5;124m'\u001b[39m\u001b[38;5;132;01m%s\u001b[39;00m\u001b[38;5;124m'\u001b[39m\u001b[38;5;124m): \u001b[39m\u001b[38;5;132;01m%r\u001b[39;00m\u001b[38;5;124m\"\u001b[39m, url, new_retry)\n",
      "\u001b[1;31mMaxRetryError\u001b[0m: HTTPSConnectionPool(host='nihitkr-chp.jovian.ai', port=443): Max retries exceeded with url: /config.json (Caused by NewConnectionError('<urllib3.connection.HTTPSConnection object at 0x00000213E3BD5B50>: Failed to establish a new connection: [Errno 11001] getaddrinfo failed'))",
      "\nDuring handling of the above exception, another exception occurred:\n",
      "\u001b[1;31mConnectionError\u001b[0m                           Traceback (most recent call last)",
      "Input \u001b[1;32mIn [8]\u001b[0m, in \u001b[0;36m<cell line: 1>\u001b[1;34m()\u001b[0m\n\u001b[1;32m----> 1\u001b[0m \u001b[43mjovian\u001b[49m\u001b[38;5;241;43m.\u001b[39;49m\u001b[43mconfigure\u001b[49m\u001b[43m(\u001b[49m\u001b[43m)\u001b[49m\n",
      "File \u001b[1;32m~\\anaconda3\\lib\\site-packages\\jovian\\utils\\configure.py:45\u001b[0m, in \u001b[0;36mconfigure\u001b[1;34m()\u001b[0m\n\u001b[0;32m     42\u001b[0m purge_creds()\n\u001b[0;32m     44\u001b[0m \u001b[38;5;66;03m# Capture and save organization ID\u001b[39;00m\n\u001b[1;32m---> 45\u001b[0m \u001b[43mensure_org\u001b[49m\u001b[43m(\u001b[49m\u001b[43mcheck_pro\u001b[49m\u001b[38;5;241;43m=\u001b[39;49m\u001b[38;5;28;43;01mFalse\u001b[39;49;00m\u001b[43m)\u001b[49m\n\u001b[0;32m     47\u001b[0m \u001b[38;5;66;03m# Ask for API Key\u001b[39;00m\n\u001b[0;32m     48\u001b[0m get_guest_key()\n",
      "File \u001b[1;32m~\\anaconda3\\lib\\site-packages\\jovian\\utils\\credentials.py:200\u001b[0m, in \u001b[0;36mensure_org\u001b[1;34m(check_pro)\u001b[0m\n\u001b[0;32m    198\u001b[0m \u001b[38;5;28;01mtry\u001b[39;00m:\n\u001b[0;32m    199\u001b[0m     config_url \u001b[38;5;241m=\u001b[39m webapp_url \u001b[38;5;241m+\u001b[39m \u001b[38;5;124m'\u001b[39m\u001b[38;5;124mconfig.json\u001b[39m\u001b[38;5;124m'\u001b[39m\n\u001b[1;32m--> 200\u001b[0m     config_res \u001b[38;5;241m=\u001b[39m \u001b[43mrequests\u001b[49m\u001b[38;5;241;43m.\u001b[39;49m\u001b[43mget\u001b[49m\u001b[43m(\u001b[49m\u001b[43mconfig_url\u001b[49m\u001b[43m)\u001b[49m\n\u001b[0;32m    201\u001b[0m \u001b[38;5;28;01mexcept\u001b[39;00m \u001b[38;5;167;01mConnectionError\u001b[39;00m \u001b[38;5;28;01mas\u001b[39;00m e:\n\u001b[0;32m    202\u001b[0m     msg \u001b[38;5;241m=\u001b[39m \u001b[38;5;124m'\u001b[39m\u001b[38;5;124mFailed to connect to \u001b[39m\u001b[38;5;124m'\u001b[39m \u001b[38;5;241m+\u001b[39m webapp_url \u001b[38;5;241m+\u001b[39m \\\n\u001b[0;32m    203\u001b[0m         \u001b[38;5;124m'\u001b[39m\u001b[38;5;124m . Please verify your organization ID and ensure you are connected to the internet.\u001b[39m\u001b[38;5;124m'\u001b[39m\n",
      "File \u001b[1;32m~\\anaconda3\\lib\\site-packages\\requests\\api.py:75\u001b[0m, in \u001b[0;36mget\u001b[1;34m(url, params, **kwargs)\u001b[0m\n\u001b[0;32m     64\u001b[0m \u001b[38;5;28;01mdef\u001b[39;00m \u001b[38;5;21mget\u001b[39m(url, params\u001b[38;5;241m=\u001b[39m\u001b[38;5;28;01mNone\u001b[39;00m, \u001b[38;5;241m*\u001b[39m\u001b[38;5;241m*\u001b[39mkwargs):\n\u001b[0;32m     65\u001b[0m     \u001b[38;5;124mr\u001b[39m\u001b[38;5;124;03m\"\"\"Sends a GET request.\u001b[39;00m\n\u001b[0;32m     66\u001b[0m \n\u001b[0;32m     67\u001b[0m \u001b[38;5;124;03m    :param url: URL for the new :class:`Request` object.\u001b[39;00m\n\u001b[1;32m   (...)\u001b[0m\n\u001b[0;32m     72\u001b[0m \u001b[38;5;124;03m    :rtype: requests.Response\u001b[39;00m\n\u001b[0;32m     73\u001b[0m \u001b[38;5;124;03m    \"\"\"\u001b[39;00m\n\u001b[1;32m---> 75\u001b[0m     \u001b[38;5;28;01mreturn\u001b[39;00m request(\u001b[38;5;124m'\u001b[39m\u001b[38;5;124mget\u001b[39m\u001b[38;5;124m'\u001b[39m, url, params\u001b[38;5;241m=\u001b[39mparams, \u001b[38;5;241m*\u001b[39m\u001b[38;5;241m*\u001b[39mkwargs)\n",
      "File \u001b[1;32m~\\anaconda3\\lib\\site-packages\\requests\\api.py:61\u001b[0m, in \u001b[0;36mrequest\u001b[1;34m(method, url, **kwargs)\u001b[0m\n\u001b[0;32m     57\u001b[0m \u001b[38;5;66;03m# By using the 'with' statement we are sure the session is closed, thus we\u001b[39;00m\n\u001b[0;32m     58\u001b[0m \u001b[38;5;66;03m# avoid leaving sockets open which can trigger a ResourceWarning in some\u001b[39;00m\n\u001b[0;32m     59\u001b[0m \u001b[38;5;66;03m# cases, and look like a memory leak in others.\u001b[39;00m\n\u001b[0;32m     60\u001b[0m \u001b[38;5;28;01mwith\u001b[39;00m sessions\u001b[38;5;241m.\u001b[39mSession() \u001b[38;5;28;01mas\u001b[39;00m session:\n\u001b[1;32m---> 61\u001b[0m     \u001b[38;5;28;01mreturn\u001b[39;00m session\u001b[38;5;241m.\u001b[39mrequest(method\u001b[38;5;241m=\u001b[39mmethod, url\u001b[38;5;241m=\u001b[39murl, \u001b[38;5;241m*\u001b[39m\u001b[38;5;241m*\u001b[39mkwargs)\n",
      "File \u001b[1;32m~\\anaconda3\\lib\\site-packages\\requests\\sessions.py:529\u001b[0m, in \u001b[0;36mSession.request\u001b[1;34m(self, method, url, params, data, headers, cookies, files, auth, timeout, allow_redirects, proxies, hooks, stream, verify, cert, json)\u001b[0m\n\u001b[0;32m    524\u001b[0m send_kwargs \u001b[38;5;241m=\u001b[39m {\n\u001b[0;32m    525\u001b[0m     \u001b[38;5;124m'\u001b[39m\u001b[38;5;124mtimeout\u001b[39m\u001b[38;5;124m'\u001b[39m: timeout,\n\u001b[0;32m    526\u001b[0m     \u001b[38;5;124m'\u001b[39m\u001b[38;5;124mallow_redirects\u001b[39m\u001b[38;5;124m'\u001b[39m: allow_redirects,\n\u001b[0;32m    527\u001b[0m }\n\u001b[0;32m    528\u001b[0m send_kwargs\u001b[38;5;241m.\u001b[39mupdate(settings)\n\u001b[1;32m--> 529\u001b[0m resp \u001b[38;5;241m=\u001b[39m \u001b[38;5;28mself\u001b[39m\u001b[38;5;241m.\u001b[39msend(prep, \u001b[38;5;241m*\u001b[39m\u001b[38;5;241m*\u001b[39msend_kwargs)\n\u001b[0;32m    531\u001b[0m \u001b[38;5;28;01mreturn\u001b[39;00m resp\n",
      "File \u001b[1;32m~\\anaconda3\\lib\\site-packages\\requests\\sessions.py:645\u001b[0m, in \u001b[0;36mSession.send\u001b[1;34m(self, request, **kwargs)\u001b[0m\n\u001b[0;32m    642\u001b[0m start \u001b[38;5;241m=\u001b[39m preferred_clock()\n\u001b[0;32m    644\u001b[0m \u001b[38;5;66;03m# Send the request\u001b[39;00m\n\u001b[1;32m--> 645\u001b[0m r \u001b[38;5;241m=\u001b[39m adapter\u001b[38;5;241m.\u001b[39msend(request, \u001b[38;5;241m*\u001b[39m\u001b[38;5;241m*\u001b[39mkwargs)\n\u001b[0;32m    647\u001b[0m \u001b[38;5;66;03m# Total elapsed time of the request (approximately)\u001b[39;00m\n\u001b[0;32m    648\u001b[0m elapsed \u001b[38;5;241m=\u001b[39m preferred_clock() \u001b[38;5;241m-\u001b[39m start\n",
      "File \u001b[1;32m~\\anaconda3\\lib\\site-packages\\requests\\adapters.py:519\u001b[0m, in \u001b[0;36mHTTPAdapter.send\u001b[1;34m(self, request, stream, timeout, verify, cert, proxies)\u001b[0m\n\u001b[0;32m    515\u001b[0m     \u001b[38;5;28;01mif\u001b[39;00m \u001b[38;5;28misinstance\u001b[39m(e\u001b[38;5;241m.\u001b[39mreason, _SSLError):\n\u001b[0;32m    516\u001b[0m         \u001b[38;5;66;03m# This branch is for urllib3 v1.22 and later.\u001b[39;00m\n\u001b[0;32m    517\u001b[0m         \u001b[38;5;28;01mraise\u001b[39;00m SSLError(e, request\u001b[38;5;241m=\u001b[39mrequest)\n\u001b[1;32m--> 519\u001b[0m     \u001b[38;5;28;01mraise\u001b[39;00m \u001b[38;5;167;01mConnectionError\u001b[39;00m(e, request\u001b[38;5;241m=\u001b[39mrequest)\n\u001b[0;32m    521\u001b[0m \u001b[38;5;28;01mexcept\u001b[39;00m ClosedPoolError \u001b[38;5;28;01mas\u001b[39;00m e:\n\u001b[0;32m    522\u001b[0m     \u001b[38;5;28;01mraise\u001b[39;00m \u001b[38;5;167;01mConnectionError\u001b[39;00m(e, request\u001b[38;5;241m=\u001b[39mrequest)\n",
      "\u001b[1;31mConnectionError\u001b[0m: HTTPSConnectionPool(host='nihitkr-chp.jovian.ai', port=443): Max retries exceeded with url: /config.json (Caused by NewConnectionError('<urllib3.connection.HTTPSConnection object at 0x00000213E3BD5B50>: Failed to establish a new connection: [Errno 11001] getaddrinfo failed'))"
     ]
    }
   ],
   "source": [
    "jovian.configure()"
   ]
  },
  {
   "cell_type": "code",
   "execution_count": null,
   "id": "b85b26a7",
   "metadata": {},
   "outputs": [],
   "source": [
    "##Enter Server Details\n",
    "model_server = \"files\\modelServer\\etc\\\\\"\n",
    "new_server = \"files\\\\newServer\\etc\\\\\""
   ]
  },
  {
   "cell_type": "code",
   "execution_count": null,
   "id": "5d37b338",
   "metadata": {},
   "outputs": [],
   "source": [
    "##Taking backup of original File Model Server\n",
    "file = input(\"Enter file to copy (without extention): \")\n",
    "original_file = new_server + file + \".txt\"\n",
    "file_name, file_extension = os.path.splitext(original_file)\n",
    "new_file = file_name + '_NEW_' + datetime.datetime.now().strftime(\"%Y-%m-%d\") + file_extension\n",
    "backup_file = file_name + '_BKP' + datetime.datetime.now().strftime(\"%Y-%m-%d\") + file_extension\n",
    "shutil.copy(original_file, backup_file)\n",
    "print(\"Backup created:\",backup_file)"
   ]
  },
  {
   "cell_type": "code",
   "execution_count": null,
   "id": "72eaa3b4",
   "metadata": {},
   "outputs": [],
   "source": [
    "##Reading entries from file in model server\n",
    "source_file = open(model_server + file + '.txt', 'r')\n",
    "s_entries = source_file.readlines()\n",
    "source_file.close()\n",
    "s_entries"
   ]
  },
  {
   "cell_type": "code",
   "execution_count": null,
   "id": "7c9edb6f",
   "metadata": {},
   "outputs": [],
   "source": [
    "##Taking entries from file in new server\n",
    "dest_file = open(original_file, 'r')\n",
    "d_entries = dest_file.readlines()\n",
    "dest_file.close\n",
    "d_entries"
   ]
  },
  {
   "cell_type": "code",
   "execution_count": null,
   "id": "94aab7a6",
   "metadata": {},
   "outputs": [],
   "source": [
    "print(\"Comparing entries from model server....\")\n",
    "\n",
    "##Comparing and adding missing entries in passwd,shadow, users.ignore\n",
    "for line in s_entries[s_entries.index('unixsa\\n'):]: #Checking for entries after unixsa\n",
    "    if (line[0]=='#'):\n",
    "        print (\"Not copied (Commented):\", line)\n",
    "        continue\n",
    "    try:\n",
    "        d_entries.index(line)\n",
    "    except:\n",
    "        d_entries.append(line)\n",
    "        print('Added:',line)\n",
    "    else:\n",
    "        print ('Already present:',line)"
   ]
  },
  {
   "cell_type": "code",
   "execution_count": null,
   "id": "5b6dcb4e",
   "metadata": {},
   "outputs": [],
   "source": [
    "##Update missing entries in file\n",
    "file = open(new_file,\"w\")\n",
    "file.writelines(d_entries)\n",
    "file.close()"
   ]
  },
  {
   "cell_type": "code",
   "execution_count": null,
   "id": "cf495732",
   "metadata": {},
   "outputs": [
    {
     "data": {
      "application/javascript": [
       "window.require && require([\"base/js/namespace\"],function(Jupyter){Jupyter.notebook.save_checkpoint()})"
      ],
      "text/plain": [
       "<IPython.core.display.Javascript object>"
      ]
     },
     "metadata": {},
     "output_type": "display_data"
    }
   ],
   "source": [
    "jovian.commit()"
   ]
  },
  {
   "cell_type": "code",
   "execution_count": null,
   "id": "c6d42e0f",
   "metadata": {},
   "outputs": [],
   "source": []
  },
  {
   "cell_type": "code",
   "execution_count": null,
   "id": "eafb18d2",
   "metadata": {},
   "outputs": [],
   "source": []
  },
  {
   "cell_type": "code",
   "execution_count": null,
   "id": "9f764673",
   "metadata": {},
   "outputs": [],
   "source": [
    "exit()"
   ]
  },
  {
   "cell_type": "code",
   "execution_count": null,
   "id": "4fd2d3a0",
   "metadata": {},
   "outputs": [],
   "source": []
  },
  {
   "cell_type": "code",
   "execution_count": null,
   "id": "6724717b",
   "metadata": {},
   "outputs": [],
   "source": [
    "#print(\"Comparing entries from model server....\")\n",
    "\n",
    "s_i = [][]\n",
    "for line in s_entries:\n",
    "    s_i[s_entries.index(line)] = line.split(:)\n",
    "s_i"
   ]
  }
 ],
 "metadata": {
  "kernelspec": {
   "display_name": "Python 3 (ipykernel)",
   "language": "python",
   "name": "python3"
  },
  "language_info": {
   "codemirror_mode": {
    "name": "ipython",
    "version": 3
   },
   "file_extension": ".py",
   "mimetype": "text/x-python",
   "name": "python",
   "nbconvert_exporter": "python",
   "pygments_lexer": "ipython3",
   "version": "3.9.12"
  }
 },
 "nbformat": 4,
 "nbformat_minor": 5
}
